
CommandNotFoundError: Your shell has not been properly configured to use 'conda activate'.
To initialize your shell, run

    $ conda init <SHELL_NAME>

Currently supported shells are:
  - bash
  - fish
  - tcsh
  - xonsh
  - zsh
  - powershell

See 'conda init --help' for more information and options.

IMPORTANT: You may need to close and restart your shell after running 'conda init'.


Traceback (most recent call last):
  File "main.py", line 352, in <module>
    hope.run()
  File "main.py", line 277, in run
    epoch_loss = self.trainModel()
  File "main.py", line 222, in trainModel
    res = self.ui_informax(self.allEmbed, self.ui_subGraphAdj, self.ui_subGraphAdj_Tensor,self.ui_subGraphAdj_Norm)
  File "/data/yangjiyuan-slurm/anaconda3/envs/torch1.5/lib/python3.8/site-packages/torch/nn/modules/module.py", line 550, in __call__
    result = self.forward(*input, **kwargs)
  File "/data/yangjiyuan-slurm/SMIN/MV_MIL/informax.py", line 57, in forward
    positive = self.encoder(features, corrupt=False)
  File "/data/yangjiyuan-slurm/anaconda3/envs/torch1.5/lib/python3.8/site-packages/torch/nn/modules/module.py", line 550, in __call__
    result = self.forward(*input, **kwargs)
  File "/data/yangjiyuan-slurm/SMIN/MV_MIL/informax.py", line 22, in forward
    features = self.conv(features)
  File "/data/yangjiyuan-slurm/anaconda3/envs/torch1.5/lib/python3.8/site-packages/torch/nn/modules/module.py", line 550, in __call__
    result = self.forward(*input, **kwargs)
  File "/data/yangjiyuan-slurm/SMIN/MV_MIL/gcn.py", line 21, in forward
    h = self.layer(self.g, h)
  File "/data/yangjiyuan-slurm/anaconda3/envs/torch1.5/lib/python3.8/site-packages/torch/nn/modules/module.py", line 550, in __call__
    result = self.forward(*input, **kwargs)
  File "/data/yangjiyuan-slurm/SMIN/MV_MIL/graphconv.py", line 62, in forward
    graph.srcdata['h'] = feat
  File "/data/yangjiyuan-slurm/anaconda3/envs/torch1.5/lib/python3.8/site-packages/dgl/view.py", line 65, in __setitem__
    self._graph.set_n_repr({key : val}, self._nodes)
  File "/data/yangjiyuan-slurm/anaconda3/envs/torch1.5/lib/python3.8/site-packages/dgl/graph.py", line 2280, in set_n_repr
    raise DGLError('Expect number of features to match number of nodes (len(u)).'
dgl._ffi.base.DGLError: Expect number of features to match number of nodes (len(u)). Got 108306 and 108191 instead.
